{
 "cells": [
  {
   "cell_type": "code",
   "execution_count": 3,
   "id": "bce9786c",
   "metadata": {},
   "outputs": [
    {
     "name": "stdout",
     "output_type": "stream",
     "text": [
      "Could not fetch URL https://pypi.org/simple/scikit-learn/: There was a problem confirming the ssl certificate: HTTPSConnectionPool(host='pypi.org', port=443): Max retries exceeded with url: /simple/scikit-learn/ (Caused by SSLError(SSLCertVerificationError(1, '[SSL: CERTIFICATE_VERIFY_FAILED] certificate verify failed: unable to get local issuer certificate (_ssl.c:1133)'))) - skipping\n",
      "Note: you may need to restart the kernel to use updated packages.\n"
     ]
    },
    {
     "name": "stderr",
     "output_type": "stream",
     "text": [
      "WARNING: Retrying (Retry(total=4, connect=None, read=None, redirect=None, status=None)) after connection broken by 'SSLError(SSLCertVerificationError(1, '[SSL: CERTIFICATE_VERIFY_FAILED] certificate verify failed: unable to get local issuer certificate (_ssl.c:1133)'))': /simple/scikit-learn/\n",
      "WARNING: Retrying (Retry(total=3, connect=None, read=None, redirect=None, status=None)) after connection broken by 'SSLError(SSLCertVerificationError(1, '[SSL: CERTIFICATE_VERIFY_FAILED] certificate verify failed: unable to get local issuer certificate (_ssl.c:1133)'))': /simple/scikit-learn/\n",
      "WARNING: Retrying (Retry(total=2, connect=None, read=None, redirect=None, status=None)) after connection broken by 'SSLError(SSLCertVerificationError(1, '[SSL: CERTIFICATE_VERIFY_FAILED] certificate verify failed: unable to get local issuer certificate (_ssl.c:1133)'))': /simple/scikit-learn/\n",
      "WARNING: Retrying (Retry(total=1, connect=None, read=None, redirect=None, status=None)) after connection broken by 'SSLError(SSLCertVerificationError(1, '[SSL: CERTIFICATE_VERIFY_FAILED] certificate verify failed: unable to get local issuer certificate (_ssl.c:1133)'))': /simple/scikit-learn/\n",
      "WARNING: Retrying (Retry(total=0, connect=None, read=None, redirect=None, status=None)) after connection broken by 'SSLError(SSLCertVerificationError(1, '[SSL: CERTIFICATE_VERIFY_FAILED] certificate verify failed: unable to get local issuer certificate (_ssl.c:1133)'))': /simple/scikit-learn/\n",
      "ERROR: Could not find a version that satisfies the requirement scikit-learn==1.5.1 (from versions: none)\n",
      "ERROR: No matching distribution found for scikit-learn==1.5.1\n"
     ]
    }
   ],
   "source": [
    "pip install scikit-learn==1.5.1"
   ]
  },
  {
   "cell_type": "code",
   "execution_count": 1,
   "id": "6e3fcf59",
   "metadata": {},
   "outputs": [
    {
     "name": "stderr",
     "output_type": "stream",
     "text": [
      "C:\\Users\\HP\\anaconda3\\lib\\site-packages\\scipy\\__init__.py:155: UserWarning: A NumPy version >=1.18.5 and <1.25.0 is required for this version of SciPy (detected version 1.26.4\n",
      "  warnings.warn(f\"A NumPy version >={np_minversion} and <{np_maxversion}\"\n"
     ]
    }
   ],
   "source": [
    "import pandas as pd\n",
    "import matplotlib.pyplot as plt\n",
    "import seaborn as sns\n",
    "import numpy as np\n",
    "from sklearn.model_selection import train_test_split,GridSearchCV,cross_val_score\n",
    "from sklearn.metrics import r2_score,mean_squared_error,mean_absolute_error\n",
    "from sklearn.preprocessing import StandardScaler\n",
    "from sklearn.linear_model import LinearRegression\n",
    "from sklearn.ensemble import GradientBoostingRegressor,RandomForestRegressor,AdaBoostRegressor\n",
    "from sklearn.tree import DecisionTreeRegressor\n",
    "from xgboost import XGBRegressor"
   ]
  },
  {
   "cell_type": "code",
   "execution_count": 1,
   "id": "34dc145b",
   "metadata": {},
   "outputs": [
    {
     "name": "stdout",
     "output_type": "stream",
     "text": [
      "Name: scikit-learn\n",
      "Version: 1.0.2\n",
      "Summary: A set of python modules for machine learning and data mining\n",
      "Home-page: http://scikit-learn.org\n",
      "Author: \n",
      "Author-email: \n",
      "License: new BSD\n",
      "Location: c:\\users\\hp\\anaconda3\\lib\\site-packages\n",
      "Requires: joblib, numpy, scipy, threadpoolctl\n",
      "Required-by: imbalanced-learn, scikeras, scikit-learn-intelex\n",
      "Note: you may need to restart the kernel to use updated packages.\n"
     ]
    }
   ],
   "source": [
    "pip show scikit-learn"
   ]
  },
  {
   "cell_type": "code",
   "execution_count": 2,
   "id": "1d79121b",
   "metadata": {},
   "outputs": [],
   "source": [
    "df=pd.read_csv('air_quality_clean.csv')"
   ]
  },
  {
   "cell_type": "code",
   "execution_count": 3,
   "id": "2cf518b9",
   "metadata": {},
   "outputs": [],
   "source": [
    "X=df[['PM2.5','PM10','NO','NO2','NOx','NH3','CO','SO2','O3','Benzene','Toluene','Xylene']]\n",
    "Y=df['AQI']"
   ]
  },
  {
   "cell_type": "code",
   "execution_count": 5,
   "id": "2ecd01e3",
   "metadata": {},
   "outputs": [],
   "source": [
    "X_train,X_test,Y_train,y_test=train_test_split(X,Y,test_size=0.2,random_state=42)"
   ]
  },
  {
   "cell_type": "code",
   "execution_count": 6,
   "id": "d1198b22",
   "metadata": {},
   "outputs": [],
   "source": [
    "scaler=StandardScaler()\n",
    "X_train=scaler.fit_transform(X_train)\n",
    "X_test=scaler.transform(X_test)"
   ]
  },
  {
   "cell_type": "code",
   "execution_count": 7,
   "id": "d0322362",
   "metadata": {},
   "outputs": [
    {
     "name": "stderr",
     "output_type": "stream",
     "text": [
      "C:\\Users\\HP\\anaconda3\\lib\\site-packages\\sklearn\\model_selection\\_validation.py:372: FitFailedWarning: \n",
      "720 fits failed out of a total of 810.\n",
      "The score on these train-test partitions for these parameters will be set to nan.\n",
      "If these failures are not expected, you can try to debug them by setting error_score='raise'.\n",
      "\n",
      "Below are more details about the failures:\n",
      "--------------------------------------------------------------------------------\n",
      "90 fits failed with the following error:\n",
      "Traceback (most recent call last):\n",
      "  File \"C:\\Users\\HP\\anaconda3\\lib\\site-packages\\sklearn\\model_selection\\_validation.py\", line 680, in _fit_and_score\n",
      "    estimator.fit(X_train, y_train, **fit_params)\n",
      "  File \"C:\\Users\\HP\\anaconda3\\lib\\site-packages\\sklearn\\ensemble\\_gb.py\", line 525, in fit\n",
      "    self._check_params()\n",
      "  File \"C:\\Users\\HP\\anaconda3\\lib\\site-packages\\sklearn\\ensemble\\_gb.py\", line 317, in _check_params\n",
      "    raise ValueError(\"subsample must be in (0,1] but was %r\" % self.subsample)\n",
      "ValueError: subsample must be in (0,1] but was 2\n",
      "\n",
      "--------------------------------------------------------------------------------\n",
      "90 fits failed with the following error:\n",
      "Traceback (most recent call last):\n",
      "  File \"C:\\Users\\HP\\anaconda3\\lib\\site-packages\\sklearn\\model_selection\\_validation.py\", line 680, in _fit_and_score\n",
      "    estimator.fit(X_train, y_train, **fit_params)\n",
      "  File \"C:\\Users\\HP\\anaconda3\\lib\\site-packages\\sklearn\\ensemble\\_gb.py\", line 525, in fit\n",
      "    self._check_params()\n",
      "  File \"C:\\Users\\HP\\anaconda3\\lib\\site-packages\\sklearn\\ensemble\\_gb.py\", line 317, in _check_params\n",
      "    raise ValueError(\"subsample must be in (0,1] but was %r\" % self.subsample)\n",
      "ValueError: subsample must be in (0,1] but was 3\n",
      "\n",
      "--------------------------------------------------------------------------------\n",
      "90 fits failed with the following error:\n",
      "Traceback (most recent call last):\n",
      "  File \"C:\\Users\\HP\\anaconda3\\lib\\site-packages\\sklearn\\model_selection\\_validation.py\", line 680, in _fit_and_score\n",
      "    estimator.fit(X_train, y_train, **fit_params)\n",
      "  File \"C:\\Users\\HP\\anaconda3\\lib\\site-packages\\sklearn\\ensemble\\_gb.py\", line 525, in fit\n",
      "    self._check_params()\n",
      "  File \"C:\\Users\\HP\\anaconda3\\lib\\site-packages\\sklearn\\ensemble\\_gb.py\", line 317, in _check_params\n",
      "    raise ValueError(\"subsample must be in (0,1] but was %r\" % self.subsample)\n",
      "ValueError: subsample must be in (0,1] but was 4\n",
      "\n",
      "--------------------------------------------------------------------------------\n",
      "90 fits failed with the following error:\n",
      "Traceback (most recent call last):\n",
      "  File \"C:\\Users\\HP\\anaconda3\\lib\\site-packages\\sklearn\\model_selection\\_validation.py\", line 680, in _fit_and_score\n",
      "    estimator.fit(X_train, y_train, **fit_params)\n",
      "  File \"C:\\Users\\HP\\anaconda3\\lib\\site-packages\\sklearn\\ensemble\\_gb.py\", line 525, in fit\n",
      "    self._check_params()\n",
      "  File \"C:\\Users\\HP\\anaconda3\\lib\\site-packages\\sklearn\\ensemble\\_gb.py\", line 317, in _check_params\n",
      "    raise ValueError(\"subsample must be in (0,1] but was %r\" % self.subsample)\n",
      "ValueError: subsample must be in (0,1] but was 5\n",
      "\n",
      "--------------------------------------------------------------------------------\n",
      "90 fits failed with the following error:\n",
      "Traceback (most recent call last):\n",
      "  File \"C:\\Users\\HP\\anaconda3\\lib\\site-packages\\sklearn\\model_selection\\_validation.py\", line 680, in _fit_and_score\n",
      "    estimator.fit(X_train, y_train, **fit_params)\n",
      "  File \"C:\\Users\\HP\\anaconda3\\lib\\site-packages\\sklearn\\ensemble\\_gb.py\", line 525, in fit\n",
      "    self._check_params()\n",
      "  File \"C:\\Users\\HP\\anaconda3\\lib\\site-packages\\sklearn\\ensemble\\_gb.py\", line 317, in _check_params\n",
      "    raise ValueError(\"subsample must be in (0,1] but was %r\" % self.subsample)\n",
      "ValueError: subsample must be in (0,1] but was 6\n",
      "\n",
      "--------------------------------------------------------------------------------\n",
      "90 fits failed with the following error:\n",
      "Traceback (most recent call last):\n",
      "  File \"C:\\Users\\HP\\anaconda3\\lib\\site-packages\\sklearn\\model_selection\\_validation.py\", line 680, in _fit_and_score\n",
      "    estimator.fit(X_train, y_train, **fit_params)\n",
      "  File \"C:\\Users\\HP\\anaconda3\\lib\\site-packages\\sklearn\\ensemble\\_gb.py\", line 525, in fit\n",
      "    self._check_params()\n",
      "  File \"C:\\Users\\HP\\anaconda3\\lib\\site-packages\\sklearn\\ensemble\\_gb.py\", line 317, in _check_params\n",
      "    raise ValueError(\"subsample must be in (0,1] but was %r\" % self.subsample)\n",
      "ValueError: subsample must be in (0,1] but was 7\n",
      "\n",
      "--------------------------------------------------------------------------------\n",
      "90 fits failed with the following error:\n",
      "Traceback (most recent call last):\n",
      "  File \"C:\\Users\\HP\\anaconda3\\lib\\site-packages\\sklearn\\model_selection\\_validation.py\", line 680, in _fit_and_score\n",
      "    estimator.fit(X_train, y_train, **fit_params)\n",
      "  File \"C:\\Users\\HP\\anaconda3\\lib\\site-packages\\sklearn\\ensemble\\_gb.py\", line 525, in fit\n",
      "    self._check_params()\n",
      "  File \"C:\\Users\\HP\\anaconda3\\lib\\site-packages\\sklearn\\ensemble\\_gb.py\", line 317, in _check_params\n",
      "    raise ValueError(\"subsample must be in (0,1] but was %r\" % self.subsample)\n",
      "ValueError: subsample must be in (0,1] but was 8\n",
      "\n",
      "--------------------------------------------------------------------------------\n",
      "90 fits failed with the following error:\n",
      "Traceback (most recent call last):\n",
      "  File \"C:\\Users\\HP\\anaconda3\\lib\\site-packages\\sklearn\\model_selection\\_validation.py\", line 680, in _fit_and_score\n",
      "    estimator.fit(X_train, y_train, **fit_params)\n",
      "  File \"C:\\Users\\HP\\anaconda3\\lib\\site-packages\\sklearn\\ensemble\\_gb.py\", line 525, in fit\n",
      "    self._check_params()\n",
      "  File \"C:\\Users\\HP\\anaconda3\\lib\\site-packages\\sklearn\\ensemble\\_gb.py\", line 317, in _check_params\n",
      "    raise ValueError(\"subsample must be in (0,1] but was %r\" % self.subsample)\n",
      "ValueError: subsample must be in (0,1] but was 9\n",
      "\n",
      "  warnings.warn(some_fits_failed_message, FitFailedWarning)\n",
      "C:\\Users\\HP\\anaconda3\\lib\\site-packages\\sklearn\\model_selection\\_search.py:969: UserWarning: One or more of the test scores are non-finite: [-4662.39438612            nan            nan            nan\n",
      "            nan            nan            nan            nan\n",
      "            nan -4448.35373289            nan            nan\n",
      "            nan            nan            nan            nan\n",
      "            nan            nan -4476.41558791            nan\n",
      "            nan            nan            nan            nan\n",
      "            nan            nan            nan -4363.2944474\n",
      "            nan            nan            nan            nan\n",
      "            nan            nan            nan            nan\n",
      " -4534.48247329            nan            nan            nan\n",
      "            nan            nan            nan            nan\n",
      "            nan -4553.99515709            nan            nan\n",
      "            nan            nan            nan            nan\n",
      "            nan            nan -4509.70228293            nan\n",
      "            nan            nan            nan            nan\n",
      "            nan            nan            nan -4598.87520386\n",
      "            nan            nan            nan            nan\n",
      "            nan            nan            nan            nan\n",
      " -4688.71384697            nan            nan            nan\n",
      "            nan            nan            nan            nan\n",
      "            nan -4889.12010238            nan            nan\n",
      "            nan            nan            nan            nan\n",
      "            nan            nan -4850.01815774            nan\n",
      "            nan            nan            nan            nan\n",
      "            nan            nan            nan -5022.38527129\n",
      "            nan            nan            nan            nan\n",
      "            nan            nan            nan            nan\n",
      " -4985.53126649            nan            nan            nan\n",
      "            nan            nan            nan            nan\n",
      "            nan -5257.54078974            nan            nan\n",
      "            nan            nan            nan            nan\n",
      "            nan            nan -5222.02315133            nan\n",
      "            nan            nan            nan            nan\n",
      "            nan            nan            nan -5596.15835761\n",
      "            nan            nan            nan            nan\n",
      "            nan            nan            nan            nan\n",
      " -5471.80268574            nan            nan            nan\n",
      "            nan            nan            nan            nan\n",
      "            nan -5828.66464832            nan            nan\n",
      "            nan            nan            nan            nan\n",
      "            nan            nan]\n",
      "  warnings.warn(\n"
     ]
    },
    {
     "data": {
      "text/plain": [
       "GridSearchCV(cv=5, estimator=GradientBoostingRegressor(),\n",
       "             param_grid={'learning_rate': array([0.1, 0.2, 0.3, 0.4, 0.5, 0.6, 0.7, 0.8, 0.9]),\n",
       "                         'n_estimators': range(100, 300, 100),\n",
       "                         'subsample': range(1, 10)},\n",
       "             scoring='neg_mean_squared_error')"
      ]
     },
     "execution_count": 7,
     "metadata": {},
     "output_type": "execute_result"
    }
   ],
   "source": [
    "parameter={'n_estimators':range(100,300,100),'learning_rate':np.arange(0.1,1,0.1),'subsample':range(1,10,1)}\n",
    "model=GradientBoostingRegressor()\n",
    "boostcv=GridSearchCV(model,param_grid=parameter,cv=5,scoring='neg_mean_squared_error',)\n",
    "boostcv.fit(X_train,Y_train)"
   ]
  },
  {
   "cell_type": "code",
   "execution_count": 8,
   "id": "31176be0",
   "metadata": {},
   "outputs": [
    {
     "name": "stdout",
     "output_type": "stream",
     "text": [
      "r2_score: 0.7559920855204054\n"
     ]
    }
   ],
   "source": [
    "pred1=boostcv.predict(X_test)\n",
    "print('r2_score:',r2_score(pred1,y_test))"
   ]
  },
  {
   "cell_type": "code",
   "execution_count": 9,
   "id": "033038fb",
   "metadata": {},
   "outputs": [],
   "source": [
    "data=[25,26,30,85,12,1,1.3,55,100,12,17,13]\n",
    "data1=np.array(data).reshape(1,-1)"
   ]
  },
  {
   "cell_type": "code",
   "execution_count": 10,
   "id": "4a3b5c85",
   "metadata": {},
   "outputs": [
    {
     "name": "stderr",
     "output_type": "stream",
     "text": [
      "C:\\Users\\HP\\anaconda3\\lib\\site-packages\\sklearn\\base.py:450: UserWarning: X does not have valid feature names, but StandardScaler was fitted with feature names\n",
      "  warnings.warn(\n"
     ]
    },
    {
     "data": {
      "text/plain": [
       "array([88.35746868])"
      ]
     },
     "execution_count": 10,
     "metadata": {},
     "output_type": "execute_result"
    }
   ],
   "source": [
    "boostcv.predict(scaler.transform(data1))"
   ]
  },
  {
   "cell_type": "code",
   "execution_count": 11,
   "id": "e7822b05",
   "metadata": {},
   "outputs": [],
   "source": [
    "import pickle"
   ]
  },
  {
   "cell_type": "code",
   "execution_count": 20,
   "id": "515ffe18",
   "metadata": {},
   "outputs": [],
   "source": [
    "pickle.dump(boostcv,open('model.pkl','wb'))\n",
    "pickle.dump(scaler,open('scaler.pkl','wb'))\n",
    "\n"
   ]
  },
  {
   "cell_type": "code",
   "execution_count": 22,
   "id": "45470532",
   "metadata": {},
   "outputs": [],
   "source": [
    "pred=pickle.load(open('model.pkl','rb'))\n",
    "sc=pickle.load(open('scaler.pkl','rb'))"
   ]
  },
  {
   "cell_type": "code",
   "execution_count": 23,
   "id": "73477358",
   "metadata": {},
   "outputs": [
    {
     "name": "stderr",
     "output_type": "stream",
     "text": [
      "C:\\Users\\HP\\anaconda3\\lib\\site-packages\\sklearn\\base.py:450: UserWarning: X does not have valid feature names, but StandardScaler was fitted with feature names\n",
      "  warnings.warn(\n"
     ]
    },
    {
     "data": {
      "text/plain": [
       "array([88.35746868])"
      ]
     },
     "execution_count": 23,
     "metadata": {},
     "output_type": "execute_result"
    }
   ],
   "source": [
    "pred.predict(sc.transform(data1))"
   ]
  },
  {
   "cell_type": "code",
   "execution_count": 6,
   "id": "248fd36e",
   "metadata": {},
   "outputs": [
    {
     "ename": "SyntaxError",
     "evalue": "invalid syntax (4270529478.py, line 4)",
     "output_type": "error",
     "traceback": [
      "\u001b[1;36m  File \u001b[1;32m\"C:\\Users\\HP\\AppData\\Local\\Temp\\ipykernel_21512\\4270529478.py\"\u001b[1;36m, line \u001b[1;32m4\u001b[0m\n\u001b[1;33m    elseif 50<number100:\u001b[0m\n\u001b[1;37m           ^\u001b[0m\n\u001b[1;31mSyntaxError\u001b[0m\u001b[1;31m:\u001b[0m invalid syntax\n"
     ]
    }
   ],
   "source": [
    "number=int(input('num:'))\n",
    "if  1<= number<50:\n",
    "    print(\"good\")\n",
    "elseif 50<number100:\n",
    "    print('bad')"
   ]
  },
  {
   "cell_type": "code",
   "execution_count": null,
   "id": "7606b45d",
   "metadata": {},
   "outputs": [],
   "source": []
  }
 ],
 "metadata": {
  "kernelspec": {
   "display_name": "Python 3 (ipykernel)",
   "language": "python",
   "name": "python3"
  },
  "language_info": {
   "codemirror_mode": {
    "name": "ipython",
    "version": 3
   },
   "file_extension": ".py",
   "mimetype": "text/x-python",
   "name": "python",
   "nbconvert_exporter": "python",
   "pygments_lexer": "ipython3",
   "version": "3.9.19"
  }
 },
 "nbformat": 4,
 "nbformat_minor": 5
}
